from django.contrib.auth import get_user_model

from rest_framework import serializers
from rest_framework.validators import UniqueTogetherValidator

from posts.models import Comment, Follow, Group, Post

User = get_user_model()


class PostSerializer(serializers.ModelSerializer):
    author = serializers.SlugRelatedField(
        read_only=True, slug_field='username',
        default=serializers.CurrentUserDefault())

    class Meta:
        fields = ('id', 'text', 'author', 'image', 'group', 'pub_date')
        model = Post


class CommentSerializer(serializers.ModelSerializer):
    author = serializers.SlugRelatedField(
        read_only=True, slug_field='username',
        default=serializers.CurrentUserDefault())

    class Meta:
        fields = ('id', 'text', 'author', 'post', 'created')
        model = Comment


class GroupSerializer(serializers.ModelSerializer):
    class Meta:
        fields = ('id', 'title', 'slug', 'description')
        model = Group


class FollowSerializer(serializers.ModelSerializer):
    user = serializers.SlugRelatedField(
        read_only=True,
        slug_field='username',
        default=serializers.CurrentUserDefault()
    )
    following = serializers.SlugRelatedField(
        queryset=User.objects.all(),
        slug_field='username',
    )

    class Meta:
        fields = ('following', 'user')
        model = Follow

        validators = [
            UniqueTogetherValidator(
                queryset=Follow.objects.all(),
                fields=('following', 'user')
            )
        ]

    def validate_following(self, following):
        if self.context.get('request').user == following:
            raise serializers.ValidationError
        return following
